Workbook
Name Anio: Config!$C$6
Name Dias_Aviso: Config!$C$15
Name Dias_Sin_Registro: Config!$C$16
Name Fecha_Inicio: Config!$C$12
Name Fijos_Activo: Fijos!$I$7:$I$28
Name Fijos_Aplica: Fijos!$G$7:$G$28
Name Fijos_Cat: Fijos!$B$7:$B$28
Name Fijos_Concepto: Fijos!$C$7:$C$28
Name Fijos_Monto: Fijos!$D$7:$D$28
Name Lista_Categorias: Listas!$A$4:$A$27
Name Lista_Estados: Listas!$H$4:$H$6
Name Lista_Fijos: Fijos!$C$7:$C$28
Name Lista_Frecuencias: Listas!$J$4:$J$5
Name Lista_Metodos: Listas!$F$4:$F$10
Name Lista_SiNo: Listas!$J$7:$J$8
Name Lista_Tipos: Listas!$D$4:$D$7
Name Meta_Ahorro: Config!$C$17
Name Q_Activa: Config!$C$10
Name Reg_Cat: Registro!$F$7:$F$402
Name Reg_Concepto: Registro!$G$7:$G$402
Name Reg_Estado: Registro!$J$7:$J$402
Name Reg_Fecha: Registro!$B$7:$B$402
Name Reg_Mes: Registro!$D$7:$D$402
Name Reg_Monto: Registro!$H$7:$H$402
Name Reg_Quincena: Registro!$C$7:$C$402
Name Reg_Tipo: Registro!$E$7:$E$402
Name Umbral_Gasto: Config!$C$14

Sheet Panel
A1: PANEL DE CONTROL · PRESUPUESTO QUINCENAL
A2: =Config!$C$5&" · año "&TEXT(Anio,"0")&" · hoy es "&TEXT(TODAY(),"DD/MM/YYYY") -> Presupuesto de Kelly · año 2026 · hoy es 31/08/2026
B4: Quincena que estás viendo | C4: ="Nº "&TEXT(Q_Activa,"0")&" · "&INDEX(Quincenas!$B$7:$B$30,Q_Activa)&" "&INDEX(Quincenas!$D$7:$D$30,Q_Activa)&" · del "&TEXT(INDEX(Quincenas!$E$7:$E$30,Q_Activa),"DD/MM")&" al "&TEXT(INDEX(Quincenas!$F$7:$F$30,Q_Activa),"DD/MM/YYYY") -> Nº 16 · Agosto Q2 · del 16/08 al 31/08/2026
B5: Días que faltan para cerrar la quincena | C5: =MAX(0,INDEX(Quincenas!$F$7:$F$30,Q_Activa)-TODAY())&" día(s)" -> 0 día(s)
B6: Último movimiento registrado | C6: =IF(COUNT(Reg_Fecha)=0,"Todavía no registras nada",TEXT(MAX(Reg_Fecha),"DD/MM/YYYY")&" (hace "&TEXT(MAX(0,TODAY()-MAX(Reg_Fecha)),"0")&" día(s))") -> Todavía no registras nada
B8: RESUMEN DE LA QUINCENA
B9: Concepto | C9: Monto | D9: % del disponible | E9: Qué significa
B10: Ingreso disponible de la quincena | C10: =INDEX(Quincenas!$I$7:$I$30,Q_Activa) -> 8500 | E10: Tu ingreso de la quincena más los ingresos extra que hayas registrado.
B11: Gastos fijos presupuestados | C11: =INDEX(Quincenas!$J$7:$J$30,Q_Activa) -> 6400 | D11: =IF($C$10=0,"",$C11/$C$10) -> 0.75294118 | E11: Lo que te toca pagar de tu lista de fijos en esta quincena.
B12: Gastos fijos ya pagados | C12: =INDEX(Quincenas!$K$7:$K$30,Q_Activa) -> 0 | D12: =IF($C$10=0,"",$C12/$C$10) -> 0 | E12: Lo que ya registraste con tipo Fijo.
B13: Gastos fijos pendientes | C13: =INDEX(Quincenas!$O$7:$O$30,Q_Activa) -> 6400 | D13: =IF($C$10=0,"",$C13/$C$10) -> 0.75294118 | E13: Lo que todavía te falta pagar de los fijos. Resérvalo.
B14: Gastos variables | C14: =INDEX(Quincenas!$L$7:$L$30,Q_Activa) -> 0 | D14: =IF($C$10=0,"",$C14/$C$10) -> 0 | E14: Comida, transporte del día, antojos, imprevistos.
B15: Ahorro apartado | C15: =INDEX(Quincenas!$M$7:$M$30,Q_Activa) -> 0 | D15: =IF($C$10=0,"",$C15/$C$10) -> 0 | E15: Lo que registraste con tipo Ahorro.
B16: Total gastado | C16: =INDEX(Quincenas!$N$7:$N$30,Q_Activa) -> 0 | D16: =IF($C$10=0,"",$C16/$C$10) -> 0 | E16: Fijos pagados + variables + ahorro.
B17: Disponible restante hoy | C17: =INDEX(Quincenas!$P$7:$P$30,Q_Activa) -> 8500 | D17: =IF($C$10=0,"",$C17/$C$10) -> 1 | E17: Disponible menos lo que ya gastaste.
B18: Restante proyectado | C18: =INDEX(Quincenas!$Q$7:$Q$30,Q_Activa) -> 2100 | D18: =IF($C$10=0,"",$C18/$C$10) -> 0.24705882 | E18: Lo que te quedará después de pagar los fijos pendientes. Este es el número que manda.
B19: % del disponible ya ejecutado | C19: =INDEX(Quincenas!$R$7:$R$30,Q_Activa) -> 0 | D19: =IF(Umbral_Gasto=0,"",Umbral_Gasto) -> 0.8 | E19: A la derecha, el umbral que configuraste para que te avise.
B20: Estado general de la quincena | C20: =INDEX(Quincenas!$S$7:$S$30,Q_Activa) -> En orden | E20: Se calcula solo comparando lo gastado contra tu disponible.
B22: ALERTAS AUTOMÁTICAS
B23: =IF($C$10=0,"URGENTE: no has puesto el ingreso de esta quincena. Ve a la hoja Quincenas, columna G, y escríbelo.","")
B24: =IF($C$16>$C$10,"URGENTE: te pasaste del disponible por C$"&TEXT($C$16-$C$10,"#,##0.00")&". Frena los gastos variables o ajusta lo que apartaste para ahorro.","")
B25: =IF(AND($C$10>0,$C$16<=$C$10,$C$19>=Umbral_Gasto),"AVISO: ya usaste el "&TEXT($C$19,"0%")&" de tu disponible y aún faltan "&TEXT(MAX(0,INDEX(Quincenas!$F$7:$F$30,Q_Activa)-TODAY()),"0")&" día(s) de quincena. Te quedan C$"&TEXT($C$17,"#,##0.00")&".","")
B26: =IF(AND($C$10>0,$C$18<0),"URGENTE: lo que te queda no alcanza para los fijos que faltan por pagar. Te faltan C$"&TEXT(-$C$18,"#,##0.00")&".","")
B27: =IF(Control!$D$36>0,"URGENTE: tienes "&TEXT(Control!$D$36,"0")&" pago(s) fijo(s) vencido(s) sin registrar. Revísalos en la hoja Control.","") -> URGENTE: tienes 1 pago(s) fijo(s) vencido(s) sin registrar. Revísalos en la hoja Control.
B28: =IF(Control!$D$37>0,"AVISO: "&TEXT(Control!$D$37,"0")&" pago(s) fijo(s) vencen dentro de los próximos "&TEXT(Dias_Aviso,"0")&" días. Déjalos listos.","") -> AVISO: 4 pago(s) fijo(s) vencen dentro de los próximos 3 días. Déjalos listos.
B29: =IF(COUNT(Reg_Fecha)=0,"AVISO: todavía no has registrado ningún movimiento en la hoja Registro.",IF(TODAY()-MAX(Reg_Fecha)>Dias_Sin_Registro,"AVISO: hace "&TEXT(TODAY()-MAX(Reg_Fecha),"0")&" días que no registras un gasto. Es muy probable que se te haya olvidado anotar algo.","")) -> AVISO: todavía no has registrado ningún movimiento en la hoja Registro.
B30: =IF(COUNTIFS(Reg_Estado,"Pendiente",Reg_Quincena,Q_Activa)>0,"AVISO: hay "&TEXT(COUNTIFS(Reg_Estado,"Pendiente",Reg_Quincena,Q_Activa),"0")&" movimiento(s) de esta quincena marcados como Pendiente. Confirma si ya los pagaste.","")
B31: =IF(SUM(Quincenas!$T$7:$T$30)>0,"AVISO: en el año hay "&TEXT(SUM(Quincenas!$T$7:$T$30),"0")&" pago(s) fijo(s) de quincenas ya cerradas que nunca registraste. Míralos en la hoja Historial.","")
B32: =IF(COUNTIF(Registro!$L$7:$L$402,"Falta*")+COUNTIF(Registro!$L$7:$L$402,"La fecha*")+COUNTIF(Registro!$L$7:$L$402,"El concepto*")>0,"AVISO: hay "&TEXT(COUNTIF(Registro!$L$7:$L$402,"Falta*")+COUNTIF(Registro!$L$7:$L$402,"La fecha*")+COUNTIF(Registro!$L$7:$L$402,"El concepto*"),"0")&" fila(s) del Registro con datos incompletos. Revisa la columna Revisión automática.","")
B33: =IF(Meta_Ahorro>0,IF($C$15>=Meta_Ahorro,"OK: ya cumpliste tu meta de ahorro de la quincena (C$"&TEXT(Meta_Ahorro,"#,##0.00")&").","INFO: te faltan C$"&TEXT(MAX(0,Meta_Ahorro-$C$15),"#,##0.00")&" para tu meta de ahorro de esta quincena."),"") -> INFO: te faltan C$1,500.00 para tu meta de ahorro de esta quincena.
B34: =IF(COUNTBLANK($B$23:$B$33)=11,"OK: todo en orden en esta quincena. Sigue registrando tus gastos el mismo día que los haces.","")
B36: RESUMEN DEL AÑO COMPLETO
B37: Ingreso total del año | C37: =SUM(Quincenas!$I$7:$I$30) -> 204000 | E37: Suma de las 24 quincenas.
B38: Gastos fijos pagados | C38: =SUM(Quincenas!$K$7:$K$30) -> 0
B39: Gastos variables | C39: =SUM(Quincenas!$L$7:$L$30) -> 0
B40: Ahorro acumulado | C40: =SUM(Quincenas!$M$7:$M$30) -> 0 | E40: Lo que has apartado en el año.
B41: Total gastado | C41: =SUM(Quincenas!$N$7:$N$30) -> 0
B42: Saldo del año | C42: =$C$37-$C$41 -> 204000 | E42: Ingreso menos todo lo gastado.
B43: % de ahorro sobre el ingreso | C43: =IF($C$37=0,0,$C$40/$C$37) -> 0 | E43: Un 10% ya es una base sana.
B44: Quincenas con sobregiro | C44: =COUNTIF(Quincenas!$S$7:$S$30,"Sobregiro") -> 0 | E44: Cuántas veces te pasaste en el año.
...

Sheet Config
A1: CONFIGURACIÓN GENERAL DEL PRESUPUESTO
B2: Las celdas amarillas con texto azul son las únicas que escribes tú. El resto se calcula solo.
B4: PARÁMETROS GENERALES
B5: Nombre del presupuesto | C5: Presupuesto de Kelly | D5: Solo es una referencia, puedes cambiarlo.
B6: Año del presupuesto | C6: 2026 | D6: Las fechas de las 24 quincenas se recalculan con este año.
B7: Moneda | C7: C$ (córdobas) | D7: El formato de moneda del archivo está fijado en córdobas.
B8: Quincena activa (0 = automática) | C8: 0 | D8: Deja 0 para que use la quincena de hoy, o escribe del 1 al 24 para revisar otra.
B9: Quincena de hoy (calculada) | C9: =IFERROR(MATCH(TODAY(),Quincenas!$E$7:$E$30,1),1) -> 16 | D9: Se deduce de la fecha de hoy contra el calendario de la hoja Quincenas.
B10: Quincena que muestran el Panel y Control | C10: =IF($C$8=0,$C$9,$C$8) -> 16 | D10: Esta es la quincena que se está analizando.
B11: Fecha de hoy | C11: =TODAY() -> 46265 | D11: Se actualiza sola cada vez que abres el archivo.
B12: Llevo el control desde | C12: 46266 | D12: Las alertas de pagos olvidados solo revisan quincenas posteriores a esta fecha, para que el archivo no te reclame meses que nunca usaste.
B13: UMBRALES DE ALERTA
B14: Avisar cuando el gasto supere este % del disponible | C14: 0.8 | D14: Con 80% el Panel te avisa apenas pasas ese porcentaje de la quincena.
B15: Días de anticipación para avisar un pago próximo | C15: 3 | D15: Un fijo que vence dentro de estos días aparece como Por vencer.
B16: Días sin registrar gastos antes de avisar | C16: 5 | D16: Si pasas más días sin anotar nada, el Panel asume que se te olvidó algo.
B17: Meta de ahorro por quincena (opcional) | C17: 1500 | D17: Deja 0 si no quieres meta. Tu ahorro es lo que sobra, esto solo lo mide.
B18: Meta de ahorro del año (24 quincenas) | C18: =$C$17*24 -> 36000 | D18: Calculado a partir de la meta quincenal.
B20: LEYENDA DE COLORES
B21: Celda amarilla con número azul | D21: Dato que escribes tú.
B22: Celda blanca con número negro | D22: Fórmula: se calcula sola, no la sobreescribas.
B23: Verde | D23: Todo en orden o pago ya registrado.
B24: Amarillo | D24: Aviso: revísalo pronto.
B25: Rojo | D25: Urgente: sobregiro o pago vencido sin registrar.
B27: CÓMO USAR EL ARCHIVO
B28: 1. Config: confirma el año, los umbrales y tu meta de ahorro.
B29: 2. Fijos: revisa los gastos fijos precargados, corrige montos y días de pago, agrega los tuyos.
B30: 3. Quincenas: escribe en la columna G el ingreso que recibes en cada quincena.
B31: 4. Registro: anota cada gasto conforme lo hagas. Todo lo demás se actualiza solo.
B32: 5. Panel: míralo a diario, ahí salen las alertas.
B33: 6. Control: revisa qué fijos ya pagaste y cuáles se te están pasando.
B34: 7. Reporte: resumen mensual y gasto anual por categoría.

Sheet Quincenas
A1: CALENDARIO DE LAS 24 QUINCENAS DEL AÑO
A2: Lo único que escribes aquí es la columna G (ingreso de la quincena). Todo lo demás se calcula solo a partir de las hojas Fijos y Registro.
A3: Q1 = del día 1 al 15 del mes · Q2 = del día 16 al último día del mes. Las fechas cambian solas si cambias el año en la hoja Config.
A6: Nº | B6: Mes | C6: Mes Nº | D6: Periodo | E6: Fecha inicio | F6: Fecha fin | G6: Ingreso de la quincena | H6: Ingresos extra | I6: Total disponible | J6: Fijos presupuestados | K6: Fijos pagados | L6: Gastos variables | M6: Ahorro apartado | N6: Total gastado | O6: Fijos pendientes | P6: Disponible restante | Q6: Restante proyectado | R6: % ejecutado | S6: Estado de la quincena | T6: Fijos sin registrar
A7: 1 | B7: Enero | C7: 1 | D7: Q1 | E7: =DATE(Anio,$C7,IF($D7="Q1",1,16)) -> 46023 | F7: =IF($D7="Q1",DATE(Anio,$C7,15),DATE(Anio,$C7+1,0)) -> 46037 | G7: 8500 | H7: =SUMIFS(Reg_Monto,Reg_Quincena,$A7,Reg_Tipo,"Ingreso extra") -> 0 | I7: =$G7+$H7 -> 8500 | J7: =SUMIFS(Fijos_Monto,Fijos_Activo,"Sí",Fijos_Aplica,$D7)+SUMIFS(Fijos_Monto,Fijos_Activo,"Sí",Fijos_Aplica,"Ambas") -> 5700 | K7: =SUMIFS(Reg_Monto,Reg_Quincena,$A7,Reg_Tipo,"Fijo") -> 0 | L7: =SUMIFS(Reg_Monto,Reg_Quincena,$A7,Reg_Tipo,"Variable") -> 0 | M7: =SUMIFS(Reg_Monto,Reg_Quincena,$A7,Reg_Tipo,"Ahorro") -> 0 | N7: =$K7+$L7+$M7 -> 0 | O7: =MAX(0,$J7-$K7) -> 5700 | P7: =$I7-$N7 -> 8500 | Q7: =$P7-$O7 -> 2800 | R7: =IF($I7=0,0,$N7/$I7) -> 0 | S7: =IF($I7=0,"Sin ingreso definido",IF($N7>$I7,"Sobregiro",IF($Q7<0,"No alcanza para los fijos",IF($R7>=Umbral_Gasto,"Cerca del límite","En orden")))) -> En orden | T7: =INDEX(Historial!$F$32:$AC$32,1,$A7) -> 0
A8: 2 | B8: Enero | C8: 1 | D8: Q2 | E8: =DATE(Anio,$C8,IF($D8="Q1",1,16)) -> 46038 | F8: =IF($D8="Q1",DATE(Anio,$C8,15),DATE(Anio,$C8+1,0)) -> 46053 | G8: 8500 | H8: =SUMIFS(Reg_Monto,Reg_Quincena,$A8,Reg_Tipo,"Ingreso extra") -> 0 | I8: =$G8+$H8 -> 8500 | J8: =SUMIFS(Fijos_Monto,Fijos_Activo,"Sí",Fijos_Aplica,$D8)+SUMIFS(Fijos_Monto,Fijos_Activo,"Sí",Fijos_Aplica,"Ambas") -> 6400 | K8: =SUMIFS(Reg_Monto,Reg_Quincena,$A8,Reg_Tipo,"Fijo") -> 0 | L8: =SUMIFS(Reg_Monto,Reg_Quincena,$A8,Reg_Tipo,"Variable") -> 0 | M8: =SUMIFS(Reg_Monto,Reg_Quincena,$A8,Reg_Tipo,"Ahorro") -> 0 | N8: =$K8+$L8+$M8 -> 0 | O8: =MAX(0,$J8-$K8) -> 6400 | P8: =$I8-$N8 -> 8500 | Q8: =$P8-$O8 -> 2100 | R8: =IF($I8=0,0,$N8/$I8) -> 0 | S8: =IF($I8=0,"Sin ingreso definido",IF($N8>$I8,"Sobregiro",IF($Q8<0,"No alcanza para los fijos",IF($R8>=Umbral_Gasto,"Cerca del límite","En orden")))) -> En orden | T8: =INDEX(Historial!$F$32:$AC$32,1,$A8) -> 0
A9: 3 | B9: Febrero | C9: 2 | D9: Q1 | E9: =DATE(Anio,$C9,IF($D9="Q1",1,16)) -> 46054 | F9: =IF($D9="Q1",DATE(Anio,$C9,15),DATE(Anio,$C9+1,0)) -> 46068 | G9: 8500 | H9: =SUMIFS(Reg_Monto,Reg_Quincena,$A9,Reg_Tipo,"Ingreso extra") -> 0 | I9: =$G9+$H9 -> 8500 | J9: =SUMIFS(Fijos_Monto,Fijos_Activo,"Sí",Fijos_Aplica,$D9)+SUMIFS(Fijos_Monto,Fijos_Activo,"Sí",Fijos_Aplica,"Ambas") -> 5700 | K9: =SUMIFS(Reg_Monto,Reg_Quincena,$A9,Reg_Tipo,"Fijo") -> 0 | L9: =SUMIFS(Reg_Monto,Reg_Quincena,$A9,Reg_Tipo,"Variable") -> 0 | M9: =SUMIFS(Reg_Monto,Reg_Quincena,$A9,Reg_Tipo,"Ahorro") -> 0 | N9: =$K9+$L9+$M9 -> 0 | O9: =MAX(0,$J9-$K9) -> 5700 | P9: =$I9-$N9 -> 8500 | Q9: =$P9-$O9 -> 2800 | R9: =IF($I9=0,0,$N9/$I9) -> 0 | S9: =IF($I9=0,"Sin ingreso definido",IF($N9>$I9,"Sobregiro",IF($Q9<0,"No alcanza para los fijos",IF($R9>=Umbral_Gasto,"Cerca del límite","En orden")))) -> En orden | T9: =INDEX(Historial!$F$32:$AC$32,1,$A9) -> 0
A10: 4 | B10: Febrero | C10: 2 | D10: Q2 | E10: =DATE(Anio,$C10,IF($D10="Q1",1,16)) -> 46069 | F10: =IF($D10="Q1",DATE(Anio,$C10,15),DATE(Anio,$C10+1,0)) -> 46081 | G10: 8500 | H10: =SUMIFS(Reg_Monto,Reg_Quincena,$A10,Reg_Tipo,"Ingreso extra") -> 0 | I10: =$G10+$H10 -> 8500 | J10: =SUMIFS(Fijos_Monto,Fijos_Activo,"Sí",Fijos_Aplica,$D10)+SUMIFS(Fijos_Monto,Fijos_Activo,"Sí",Fijos_Aplica,"Ambas") -> 6400 | K10: =SUMIFS(Reg_Monto,Reg_Quincena,$A10,Reg_Tipo,"Fijo") -> 0 | L10: =SUMIFS(Reg_Monto,Reg_Quincena,$A10,Reg_Tipo,"Variable") -> 0 | M10: =SUMIFS(Reg_Monto,Reg_Quincena,$A10,Reg_Tipo,"Ahorro") -> 0 | N10: =$K10+$L10+$M10 -> 0 | O10: =MAX(0,$J10-$K10) -> 6400 | P10: =$I10-$N10 -> 8500 | Q10: =$P10-$O10 -> 2100 | R10: =IF($I10=0,0,$N10/$I10) -> 0 | S10: =IF($I10=0,"Sin ingreso definido",IF($N10>$I10,"Sobregiro",IF($Q10<0,"No alcanza para los fijos",IF($R10>=Umbral_Gasto,"Cerca del límite","En orden")))) -> En orden | T10: =INDEX(Historial!$F$32:$AC$32,1,$A10) -> 0
A11: 5 | B11: Marzo | C11: 3 | D11: Q1 | E11: =DATE(Anio,$C11,IF($D11="Q1",1,16)) -> 46082 | F11: =IF($D11="Q1",DATE(Anio,$C11,15),DATE(Anio,$C11+1,0)) -> 46096 | G11: 8500 | H11: =SUMIFS(Reg_Monto,Reg_Quincena,$A11,Reg_Tipo,"Ingreso extra") -> 0 | I11: =$G11+$H11 -> 8500 | J11: =SUMIFS(Fijos_Monto,Fijos_Activo,"Sí",Fijos_Aplica,$D11)+SUMIFS(Fijos_Monto,Fijos_Activo,"Sí",Fijos_Aplica,"Ambas") -> 5700 | K11: =SUMIFS(Reg_Monto,Reg_Quincena,$A11,Reg_Tipo,"Fijo") -> 0 | L11: =SUMIFS(Reg_Monto,Reg_Quincena,$A11,Reg_Tipo,"Variable") -> 0 | M11: =SUMIFS(Reg_Monto,Reg_Quincena,$A11,Reg_Tipo,"Ahorro") -> 0 | N11: =$K11+$L11+$M11 -> 0 | O11: =MAX(0,$J11-$K11) -> 5700 | P11: =$I11-$N11 -> 8500 | Q11: =$P11-$O11 -> 2800 | R11: =IF($I11=0,0,$N11/$I11) -> 0 | S11: =IF($I11=0,"Sin ingreso definido",IF($N11>$I11,"Sobregiro",IF($Q11<0,"No alcanza para los fijos",IF($R11>=Umbral_Gasto,"Cerca del límite","En orden")))) -> En orden | T11: =INDEX(Historial!$F$32:$AC$32,1,$A11) -> 0
A12: 6 | B12: Marzo | C12: 3 | D12: Q2 | E12: =DATE(Anio,$C12,IF($D12="Q1",1,16)) -> 46097 | F12: =IF($D12="Q1",DATE(Anio,$C12,15),DATE(Anio,$C12+1,0)) -> 46112 | G12: 8500 | H12: =SUMIFS(Reg_Monto,Reg_Quincena,$A12,Reg_Tipo,"Ingreso extra") -> 0 | I12: =$G12+$H12 -> 8500 | J12: =SUMIFS(Fijos_Monto,Fijos_Activo,"Sí",Fijos_Aplica,$D12)+SUMIFS(Fijos_Monto,Fijos_Activo,"Sí",Fijos_Aplica,"Ambas") -> 6400 | K12: =SUMIFS(Reg_Monto,Reg_Quincena,$A12,Reg_Tipo,"Fijo") -> 0 | L12: =SUMIFS(Reg_Monto,Reg_Quincena,$A12,Reg_Tipo,"Variable") -> 0 | M12: =SUMIFS(Reg_Monto,Reg_Quincena,$A12,Reg_Tipo,"Ahorro") -> 0 | N12: =$K12+$L12+$M12 -> 0 | O12: =MAX(0,$J12-$K12) -> 6400 | P12: =$I12-$N12 -> 8500 | Q12: =$P12-$O12 -> 2100 | R12: =IF($I12=0,0,$N12/$I12) -> 0 | S12: =IF($I12=0,"Sin ingreso definido",IF($N12>$I12,"Sobregiro",IF($Q12<0,"No alcanza para los fijos",IF($R12>=Umbral_Gasto,"Cerca del límite","En orden")))) -> En orden | T12: =INDEX(Historial!$F$32:$AC$32,1,$A12) -> 0
A13: 7 | B13: Abril | C13: 4 | D13: Q1 | E13: =DATE(Anio,$C13,IF($D13="Q1",1,16)) -> 46113 | F13: =IF($D13="Q1",DATE(Anio,$C13,15),DATE(Anio,$C13+1,0)) -> 46127 | G13: 8500 | H13: =SUMIFS(Reg_Monto,Reg_Quincena,$A13,Reg_Tipo,"Ingreso extra") -> 0 | I13: =$G13+$H13 -> 8500 | J13: =SUMIFS(Fijos_Monto,Fijos_Activo,"Sí",Fijos_Aplica,$D13)+SUMIFS(Fijos_Monto,Fijos_Activo,"Sí",Fijos_Aplica,"Ambas") -> 5700 | K13: =SUMIFS(Reg_Monto,Reg_Quincena,$A13,Reg_Tipo,"Fijo") -> 0 | L13: =SUMIFS(Reg_Monto,Reg_Quincena,$A13,Reg_Tipo,"Variable") -> 0 | M13: =SUMIFS(Reg_Monto,Reg_Quincena,$A13,Reg_Tipo,"Ahorro") -> 0 | N13: =$K13+$L13+$M13 -> 0 | O13: =MAX(0,$J13-$K13) -> 5700 | P13: =$I13-$N13 -> 8500 | Q13: =$P13-$O13 -> 2800 | R13: =IF($I13=0,0,$N13/$I13) -> 0 | S13: =IF($I13=0,"Sin ingreso definido",IF($N13>$I13,"Sobregiro",IF($Q13<0,"No alcanza para los fijos",IF($R13>=Umbral_Gasto,"Cerca del límite","En orden")))) -> En orden | T13: =INDEX(Historial!$F$32:$AC$32,1,$A13) -> 0
A14: 8 | B14: Abril | C14: 4 | D14: Q2 | E14: =DATE(Anio,$C14,IF($D14="Q1",1,16)) -> 46128 | F14: =IF($D14="Q1",DATE(Anio,$C14,15),DATE(Anio,$C14+1,0)) -> 46142 | G14: 8500 | H14: =SUMIFS(Reg_Monto,Reg_Quincena,$A14,Reg_Tipo,"Ingreso extra") -> 0 | I14: =$G14+$H14 -> 8500 | J14: =SUMIFS(Fijos_Monto,Fijos_Activo,"Sí",Fijos_Aplica,$D14)+SUMIFS(Fijos_Monto,Fijos_Activo,"Sí",Fijos_Aplica,"Ambas") -> 6400 | K14: =SUMIFS(Reg_Monto,Reg_Quincena,$A14,Reg_Tipo,"Fijo") -> 0 | L14: =SUMIFS(Reg_Monto,Reg_Quincena,$A14,Reg_Tipo,"Variable") -> 0 | M14: =SUMIFS(Reg_Monto,Reg_Quincena,$A14,Reg_Tipo,"Ahorro") -> 0 | N14: =$K14+$L14+$M14 -> 0 | O14: =MAX(0,$J14-$K14) -> 6400 | P14: =$I14-$N14 -> 8500 | Q14: =$P14-$O14 -> 2100 | R14: =IF($I14=0,0,$N14/$I14) -> 0 | S14: =IF($I14=0,"Sin ingreso definido",IF($N14>$I14,"Sobregiro",IF($Q14<0,"No alcanza para los fijos",IF($R14>=Umbral_Gasto,"Cerca del límite","En orden")))) -> En orden | T14: =INDEX(Historial!$F$32:$AC$32,1,$A14) -> 0
A15: 9 | B15: Mayo | C15: 5 | D15: Q1 | E15: =DATE(Anio,$C15,IF($D15="Q1",1,16)) -> 46143 | F15: =IF($D15="Q1",DATE(Anio,$C15,15),DATE(Anio,$C15+1,0)) -> 46157 | G15: 8500 | H15: =SUMIFS(Reg_Monto,Reg_Quincena,$A15,Reg_Tipo,"Ingreso extra") -> 0 | I15: =$G15+$H15 -> 8500 | J15: =SUMIFS(Fijos_Monto,Fijos_Activo,"Sí",Fijos_Aplica,$D15)+SUMIFS(Fijos_Monto,Fijos_Activo,"Sí",Fijos_Aplica,"Ambas") -> 5700 | K15: =SUMIFS(Reg_Monto,Reg_Quincena,$A15,Reg_Tipo,"Fijo") -> 0 | L15: =SUMIFS(Reg_Monto,Reg_Quincena,$A15,Reg_Tipo,"Variable") -> 0 | M15: =SUMIFS(Reg_Monto,Reg_Quincena,$A15,Reg_Tipo,"Ahorro") -> 0 | N15: =$K15+$L15+$M15 -> 0 | O15: =MAX(0,$J15-$K15) -> 5700 | P15: =$I15-$N15 -> 8500 | Q15: =$P15-$O15 -> 2800 | R15: =IF($I15=0,0,$N15/$I15) -> 0 | S15: =IF($I15=0,"Sin ingreso definido",IF($N15>$I15,"Sobregiro",IF($Q15<0,"No alcanza para los fijos",IF($R15>=Umbral_Gasto,"Cerca del límite","En orden")))) -> En orden | T15: =INDEX(Historial!$F$32:$AC$32,1,$A15) -> 0
A16: 10 | B16: Mayo | C16: 5 | D16: Q2 | E16: =DATE(Anio,$C16,IF($D16="Q1",1,16)) -> 46158 | F16: =IF($D16="Q1",DATE(Anio,$C16,15),DATE(Anio,$C16+1,0)) -> 46173 | G16: 8500 | H16: =SUMIFS(Reg_Monto,Reg_Quincena,$A16,Reg_Tipo,"Ingreso extra") -> 0 | I16: =$G16+$H16 -> 8500 | J16: =SUMIFS(Fijos_Monto,Fijos_Activo,"Sí",Fijos_Aplica,$D16)+SUMIFS(Fijos_Monto,Fijos_Activo,"Sí",Fijos_Aplica,"Ambas") -> 6400 | K16: =SUMIFS(Reg_Monto,Reg_Quincena,$A16,Reg_Tipo,"Fijo") -> 0 | L16: =SUMIFS(Reg_Monto,Reg_Quincena,$A16,Reg_Tipo,"Variable") -> 0 | M16: =SUMIFS(Reg_Monto,Reg_Quincena,$A16,Reg_Tipo,"Ahorro") -> 0 | N16: =$K16+$L16+$M16 -> 0 | O16: =MAX(0,$J16-$K16) -> 6400 | P16: =$I16-$N16 -> 8500 | Q16: =$P16-$O16 -> 2100 | R16: =IF($I16=0,0,$N16/$I16) -> 0 | S16: =IF($I16=0,"Sin ingreso definido",IF($N16>$I16,"Sobregiro",IF($Q16<0,"No alcanza para los fijos",IF($R16>=Umbral_Gasto,"Cerca del límite","En orden")))) -> En orden | T16: =INDEX(Historial!$F$32:$AC$32,1,$A16) -> 0
A17: 11 | B17: Junio | C17: 6 | D17: Q1 | E17: =DATE(Anio,$C17,IF($D17="Q1",1,16)) -> 46174 | F17: =IF($D17="Q1",DATE(Anio,$C17,15),DATE(Anio,$C17+1,0)) -> 46188 | G17: 8500 | H17: =SUMIFS(Reg_Monto,Reg_Quincena,$A17,Reg_Tipo,"Ingreso extra") -> 0 | I17: =$G17+$H17 -> 8500 | J17: =SUMIFS(Fijos_Monto,Fijos_Activo,"Sí",Fijos_Aplica,$D17)+SUMIFS(Fijos_Monto,Fijos_Activo,"Sí",Fijos_Aplica,"Ambas") -> 5700 | K17: =SUMIFS(Reg_Monto,Reg_Quincena,$A17,Reg_Tipo,"Fijo") -> 0 | L17: =SUMIFS(Reg_Monto,Reg_Quincena,$A17,Reg_Tipo,"Variable") -> 0 | M17: =SUMIFS(Reg_Monto,Reg_Quincena,$A17,Reg_Tipo,"Ahorro") -> 0 | N17: =$K17+$L17+$M17 -> 0 | O17: =MAX(0,$J17-$K17) -> 5700 | P17: =$I17-$N17 -> 8500 | Q17: =$P17-$O17 -> 2800 | R17: =IF($I17=0,0,$N17/$I17) -> 0 | S17: =IF($I17=0,"Sin ingreso definido",IF($N17>$I17,"Sobregiro",IF($Q17<0,"No alcanza para los fijos",IF($R17>=Umbral_Gasto,"Cerca del límite","En orden")))) -> En orden | T17: =INDEX(Historial!$F$32:$AC$32,1,$A17) -> 0
A18: 12 | B18: Junio | C18: 6 | D18: Q2 | E18: =DATE(Anio,$C18,IF($D18="Q1",1,16)) -> 46189 | F18: =IF($D18="Q1",DATE(Anio,$C18,15),DATE(Anio,$C18+1,0)) -> 46203 | G18: 8500 | H18: =SUMIFS(Reg_Monto,Reg_Quincena,$A18,Reg_Tipo,"Ingreso extra") -> 0 | I18: =$G18+$H18 -> 8500 | J18: =SUMIFS(Fijos_Monto,Fijos_Activo,"Sí",Fijos_Aplica,$D18)+SUMIFS(Fijos_Monto,Fijos_Activo,"Sí",Fijos_Aplica,"Ambas") -> 6400 | K18: =SUMIFS(Reg_Monto,Reg_Quincena,$A18,Reg_Tipo,"Fijo") -> 0 | L18: =SUMIFS(Reg_Monto,Reg_Quincena,$A18,Reg_Tipo,"Variable") -> 0 | M18: =SUMIFS(Reg_Monto,Reg_Quincena,$A18,Reg_Tipo,"Ahorro") -> 0 | N18: =$K18+$L18+$M18 -> 0 | O18: =MAX(0,$J18-$K18) -> 6400 | P18: =$I18-$N18 -> 8500 | Q18: =$P18-$O18 -> 2100 | R18: =IF($I18=0,0,$N18/$I18) -> 0 | S18: =IF($I18=0,"Sin ingreso definido",IF($N18>$I18,"Sobregiro",IF($Q18<0,"No alcanza para los fijos",IF($R18>=Umbral_Gasto,"Cerca del límite","En orden")))) -> En orden | T18: =INDEX(Historial!$F$32:$AC$32,1,$A18) -> 0
... A30: 24 | B30: Diciembre | C30: 12 | D30: Q2 | E30: =DATE(Anio,$C30,IF($D30="Q1",1,16)) -> 46372 | F30: =IF($D30="Q1",DATE(Anio,$C30,15),DATE(Anio,$C30+1,0)) -> 46387 | G30: 8500 | H30: =SUMIFS(Reg_Monto,Reg_Quincena,$A30,Reg_Tipo,"Ingreso extra") -> 0 | I30: =$G30+$H30 -> 8500 | J30: =SUMIFS(Fijos_Monto,Fijos_Activo,"Sí",Fijos_Aplica,$D30)+SUMIFS(Fijos_Monto,Fijos_Activo,"Sí",Fijos_Aplica,"Ambas") -> 6400 | K30: =SUMIFS(Reg_Monto,Reg_Quincena,$A30,Reg_Tipo,"Fijo") -> 0 | L30: =SUMIFS(Reg_Monto,Reg_Quincena,$A30,Reg_Tipo,"Variable") -> 0 | M30: =SUMIFS(Reg_Monto,Reg_Quincena,$A30,Reg_Tipo,"Ahorro") -> 0 | N30: =$K30+$L30+$M30 -> 0 | O30: =MAX(0,$J30-$K30) -> 6400 | P30: =$I30-$N30 -> 8500 | Q30: =$P30-$O30 -> 2100 | R30: =IF($I30=0,0,$N30/$I30) -> 0 | S30: =IF($I30=0,"Sin ingreso definido",IF($N30>$I30,"Sobregiro",IF($Q30<0,"No alcanza para los fijos",IF($R30>=Umbral_Gasto,"Cerca del límite","En orden")))) -> En orden | T30: =INDEX(Historial!$F$32:$AC$32,1,$A30) -> 0
A31: TOTAL DEL AÑO | G31: =SUM(G7:G30) -> 204000 | H31: =SUM(H7:H30) -> 0 | I31: =SUM(I7:I30) -> 204000 | J31: =SUM(J7:J30) -> 145200 | K31: =SUM(K7:K30) -> 0 | L31: =SUM(L7:L30) -> 0 | M31: =SUM(M7:M30) -> 0 | N31: =SUM(N7:N30) -> 0 | ... Q31: =SUM(Q7:Q30) -> 58800 | R31: =IF($I31=0,0,$N31/$I31) -> 0 | S31: =COUNTIF($S$7:$S$30,"Sobregiro")&" quincena(s) con sobregiro" -> 0 quincena(s) con sobregiro | T31: =SUM(T7:T30) -> 0

Sheet Fijos
A1: GASTOS FIJOS · tu lista base de compromisos
A2: Escribe aquí todo lo que pagas siempre. Las columnas amarillas son tuyas: categoría, concepto, monto, día de pago, frecuencia, método y si está activo.
A3: Los montos precargados son un punto de partida realista, cámbialos por los tuyos. Para dar de baja un fijo pon 'No' en Activo, así conservas el histórico.
A6: ID | B6: Categoría | C6: Concepto | D6: Monto estimado | E6: Día de pago | F6: Frecuencia | G6: Aplica a | H6: Método de pago | I6: Activo | J6: Costo mensual | K6: Costo anual | L6: Notas
A7: =IF($C7="","","F"&TEXT(ROW()-6,"00")) -> F01 | B7: Vivienda | C7: Apoyo Casa | D7: 2500 | E7: 5 | F7: Quincenal | G7: =IF($C7="","",IF($F7="Quincenal","Ambas",IF($E7<=15,"Q1","Q2"))) -> Ambas | H7: Transferencia | I7: Sí | J7: =IF($C7="","",IF($I7="No",0,IF($F7="Quincenal",$D7*2,$D7))) -> 5000 | K7: =IF($C7="","",$J7*12) -> 60000
A8: =IF($C8="","","F"&TEXT(ROW()-6,"00")) -> F02 | B8: Transporte | C8: Pasajes y transporte | D8: 2400 | E8: 1 | F8: Quincenal | G8: =IF($C8="","",IF($F8="Quincenal","Ambas",IF($E8<=15,"Q1","Q2"))) -> Ambas | H8: Efectivo | I8: Sí | J8: =IF($C8="","",IF($I8="No",0,IF($F8="Quincenal",$D8*2,$D8))) -> 4800 | K8: =IF($C8="","",$J8*12) -> 57600
A9: =IF($C9="","","F"&TEXT(ROW()-6,"00")) -> F03 | B9: Deudas y tarjetas | C9: Pago Perfume | D9: 400 | E9: 18 | F9: Quincenal | G9: =IF($C9="","",IF($F9="Quincenal","Ambas",IF($E9<=15,"Q1","Q2"))) -> Ambas | H9: Transferencia | I9: Sí | J9: =IF($C9="","",IF($I9="No",0,IF($F9="Quincenal",$D9*2,$D9))) -> 800 | K9: =IF($C9="","",$J9*12) -> 9600
A10: =IF($C10="","","F"&TEXT(ROW()-6,"00")) -> F04 | B10: Suscripciones | C10: Streaming | D10: 400 | E10: 12 | F10: Quincenal | G10: =IF($C10="","",IF($F10="Quincenal","Ambas",IF($E10<=15,"Q1","Q2"))) -> Ambas | H10: Transferencia | I10: Sí | J10: =IF($C10="","",IF($I10="No",0,IF($F10="Quincenal",$D10*2,$D10))) -> 800 | K10: =IF($C10="","",$J10*12) -> 9600
A11: =IF($C11="","","F"&TEXT(ROW()-6,"00")) -> F05 | B11: Internet y teléfono | C11: Telefono | D11: 700 | E11: 28 | F11: Mensual | G11: =IF($C11="","",IF($F11="Quincenal","Ambas",IF($E11<=15,"Q1","Q2"))) -> Q2 | H11: Transferencia | I11: Sí | J11: =IF($C11="","",IF($I11="No",0,IF($F11="Quincenal",$D11*2,$D11))) -> 700 | K11: =IF($C11="","",$J11*12) -> 8400
A12: =IF($C12="","","F"&TEXT(ROW()-6,"00")) | G12: =IF($C12="","",IF($F12="Quincenal","Ambas",IF($E12<=15,"Q1","Q2"))) | J12: =IF($C12="","",IF($I12="No",0,IF($F12="Quincenal",$D12*2,$D12))) | K12: =IF($C12="","",$J12*12)
A13: =IF($C13="","","F"&TEXT(ROW()-6,"00")) | G13: =IF($C13="","",IF($F13="Quincenal","Ambas",IF($E13<=15,"Q1","Q2"))) | J13: =IF($C13="","",IF($I13="No",0,IF($F13="Quincenal",$D13*2,$D13))) | K13: =IF($C13="","",$J13*12)
A14: =IF($C14="","","F"&TEXT(ROW()-6,"00")) | G14: =IF($C14="","",IF($F14="Quincenal","Ambas",IF($E14<=15,"Q1","Q2"))) | J14: =IF($C14="","",IF($I14="No",0,IF($F14="Quincenal",$D14*2,$D14))) | K14: =IF($C14="","",$J14*12)
A15: =IF($C15="","","F"&TEXT(ROW()-6,"00")) | G15: =IF($C15="","",IF($F15="Quincenal","Ambas",IF($E15<=15,"Q1","Q2"))) | J15: =IF($C15="","",IF($I15="No",0,IF($F15="Quincenal",$D15*2,$D15))) | K15: =IF($C15="","",$J15*12)
A16: =IF($C16="","","F"&TEXT(ROW()-6,"00")) | G16: =IF($C16="","",IF($F16="Quincenal","Ambas",IF($E16<=15,"Q1","Q2"))) | J16: =IF($C16="","",IF($I16="No",0,IF($F16="Quincenal",$D16*2,$D16))) | K16: =IF($C16="","",$J16*12)
A17: =IF($C17="","","F"&TEXT(ROW()-6,"00")) | G17: =IF($C17="","",IF($F17="Quincenal","Ambas",IF($E17<=15,"Q1","Q2"))) | J17: =IF($C17="","",IF($I17="No",0,IF($F17="Quincenal",$D17*2,$D17))) | K17: =IF($C17="","",$J17*12)
A18: =IF($C18="","","F"&TEXT(ROW()-6,"00")) | G18: =IF($C18="","",IF($F18="Quincenal","Ambas",IF($E18<=15,"Q1","Q2"))) | J18: =IF($C18="","",IF($I18="No",0,IF($F18="Quincenal",$D18*2,$D18))) | K18: =IF($C18="","",$J18*12)
A19: =IF($C19="","","F"&TEXT(ROW()-6,"00")) | G19: =IF($C19="","",IF($F19="Quincenal","Ambas",IF($E19<=15,"Q1","Q2"))) | J19: =IF($C19="","",IF($I19="No",0,IF($F19="Quincenal",$D19*2,$D19))) | K19: =IF($C19="","",$J19*12)
A20: =IF($C20="","","F"&TEXT(ROW()-6,"00")) | G20: =IF($C20="","",IF($F20="Quincenal","Ambas",IF($E20<=15,"Q1","Q2"))) | J20: =IF($C20="","",IF($I20="No",0,IF($F20="Quincenal",$D20*2,$D20))) | K20: =IF($C20="","",$J20*12)
A21: =IF($C21="","","F"&TEXT(ROW()-6,"00")) | G21: =IF($C21="","",IF($F21="Quincenal","Ambas",IF($E21<=15,"Q1","Q2"))) | J21: =IF($C21="","",IF($I21="No",0,IF($F21="Quincenal",$D21*2,$D21))) | K21: =IF($C21="","",$J21*12)
A22: =IF($C22="","","F"&TEXT(ROW()-6,"00")) | G22: =IF($C22="","",IF($F22="Quincenal","Ambas",IF($E22<=15,"Q1","Q2"))) | J22: =IF($C22="","",IF($I22="No",0,IF($F22="Quincenal",$D22*2,$D22))) | K22: =IF($C22="","",$J22*12)
A23: =IF($C23="","","F"&TEXT(ROW()-6,"00")) | G23: =IF($C23="","",IF($F23="Quincenal","Ambas",IF($E23<=15,"Q1","Q2"))) | J23: =IF($C23="","",IF($I23="No",0,IF($F23="Quincenal",$D23*2,$D23))) | K23: =IF($C23="","",$J23*12)
... A28: =IF($C28="","","F"&TEXT(ROW()-6,"00")) | G28: =IF($C28="","",IF($F28="Quincenal","Ambas",IF($E28<=15,"Q1","Q2"))) | J28: =IF($C28="","",IF($I28="No",0,IF($F28="Quincenal",$D28*2,$D28))) | K28: =IF($C28="","",$J28*12)
A30: TOTAL DE GASTOS FIJOS ACTIVOS | J30: =SUM(J7:J28) -> 12100 | K30: =SUM(K7:K28) -> 145200
B32: RESUMEN DE TUS FIJOS
B33: Fijos que se pagan en la primera quincena (Q1) | E33: =SUMIFS(Fijos_Monto,Fijos_Activo,"Sí",Fijos_Aplica,"Q1")+SUMIFS(Fijos_Monto,Fijos_Activo,"Sí",Fijos_Aplica,"Ambas") -> 5700
B34: Fijos que se pagan en la segunda quincena (Q2) | E34: =SUMIFS(Fijos_Monto,Fijos_Activo,"Sí",Fijos_Aplica,"Q2")+SUMIFS(Fijos_Monto,Fijos_Activo,"Sí",Fijos_Aplica,"Ambas") -> 6400
B35: Total mensual de fijos | E35: =$J$30 -> 12100
B36: Total anual de fijos | E36: =$K$30 -> 145200
B37: Cantidad de fijos activos | E37: =COUNTIFS(Fijos_Activo,"Sí") -> 5
B38: Cantidad de fijos dados de baja | E38: =COUNTIFS(Fijos_Activo,"No") -> 0

Sheet Registro
A1: REGISTRO DE MOVIMIENTOS · aquí anotas cada gasto
A2: Escribe solo las columnas amarillas: fecha, tipo, categoría, concepto, monto, método, estado y notas. La quincena, el mes y la revisión se calculan solos.
A3: Tipo: Fijo (algo de tu lista de gastos fijos) · Variable (lo demás) · Ahorro (lo que apartas) · Ingreso extra (dinero que entra fuera del salario, suma al disponible).
A4: Para que un fijo se marque como pagado en la hoja Control, el Concepto tiene que ser exactamente el mismo de la hoja Fijos. Usa el desplegable y no lo escribas a mano.
A6: Nº | B6: Fecha | C6: Quincena | D6: Mes | E6: Tipo | F6: Categoría | G6: Concepto | H6: Monto | I6: Método de pago | J6: Estado | K6: Notas | L6: Revisión automática
A7: =IF($B7="","",COUNT($B$7:$B7)) | C7: =IF($B7="","",IFERROR(MATCH($B7,Quincenas!$E$7:$E$30,1),"")) | D7: =IF($B7="","",MONTH($B7)) | E7: Variable | F7: Ahorro | G7: Pago Perfume | L7: =IF($B7="","",IF($C7="","La fecha está fuera del año configurado",IF($E7="","Falta indicar el tipo",IF($H7="","Falta el monto",IF($F7="","Falta la categoría",IF(AND($E7="Fijo",COUNTIF(Fijos_Concepto,$G7)=0),"El concepto no existe en la hoja Fijos",IF($J7="Pendiente","Movimiento pendiente de pago","OK")))))))
A8: =IF($B8="","",COUNT($B$7:$B8)) | C8: =IF($B8="","",IFERROR(MATCH($B8,Quincenas!$E$7:$E$30,1),"")) | D8: =IF($B8="","",MONTH($B8)) | L8: =IF($B8="","",IF($C8="","La fecha está fuera del año configurado",IF($E8="","Falta indicar el tipo",IF($H8="","Falta el monto",IF($F8="","Falta la categoría",IF(AND($E8="Fijo",COUNTIF(Fijos_Concepto,$G8)=0),"El concepto no existe en la hoja Fijos",IF($J8="Pendiente","Movimiento pendiente de pago","OK")))))))
A9: =IF($B9="","",COUNT($B$7:$B9)) | C9: =IF($B9="","",IFERROR(MATCH($B9,Quincenas!$E$7:$E$30,1),"")) | D9: =IF($B9="","",MONTH($B9)) | L9: =IF($B9="","",IF($C9="","La fecha está fuera del año configurado",IF($E9="","Falta indicar el tipo",IF($H9="","Falta el monto",IF($F9="","Falta la categoría",IF(AND($E9="Fijo",COUNTIF(Fijos_Concepto,$G9)=0),"El concepto no existe en la hoja Fijos",IF($J9="Pendiente","Movimiento pendiente de pago","OK")))))))
A10: =IF($B10="","",COUNT($B$7:$B10)) | C10: =IF($B10="","",IFERROR(MATCH($B10,Quincenas!$E$7:$E$30,1),"")) | D10: =IF($B10="","",MONTH($B10)) | L10: =IF($B10="","",IF($C10="","La fecha está fuera del año configurado",IF($E10="","Falta indicar el tipo",IF($H10="","Falta el monto",IF($F10="","Falta la categoría",IF(AND($E10="Fijo",COUNTIF(Fijos_Concepto,$G10)=0),"El concepto no existe en la hoja Fijos",IF($J10="Pendiente","Movimiento pendiente de pago","OK")))))))
A11: =IF($B11="","",COUNT($B$7:$B11)) | C11: =IF($B11="","",IFERROR(MATCH($B11,Quincenas!$E$7:$E$30,1),"")) | D11: =IF($B11="","",MONTH($B11)) | L11: =IF($B11="","",IF($C11="","La fecha está fuera del año configurado",IF($E11="","Falta indicar el tipo",IF($H11="","Falta el monto",IF($F11="","Falta la categoría",IF(AND($E11="Fijo",COUNTIF(Fijos_Concepto,$G11)=0),"El concepto no existe en la hoja Fijos",IF($J11="Pendiente","Movimiento pendiente de pago","OK")))))))
A12: =IF($B12="","",COUNT($B$7:$B12)) | C12: =IF($B12="","",IFERROR(MATCH($B12,Quincenas!$E$7:$E$30,1),"")) | D12: =IF($B12="","",MONTH($B12)) | L12: =IF($B12="","",IF($C12="","La fecha está fuera del año configurado",IF($E12="","Falta indicar el tipo",IF($H12="","Falta el monto",IF($F12="","Falta la categoría",IF(AND($E12="Fijo",COUNTIF(Fijos_Concepto,$G12)=0),"El concepto no existe en la hoja Fijos",IF($J12="Pendiente","Movimiento pendiente de pago","OK")))))))
A13: =IF($B13="","",COUNT($B$7:$B13)) | C13: =IF($B13="","",IFERROR(MATCH($B13,Quincenas!$E$7:$E$30,1),"")) | D13: =IF($B13="","",MONTH($B13)) | L13: =IF($B13="","",IF($C13="","La fecha está fuera del año configurado",IF($E13="","Falta indicar el tipo",IF($H13="","Falta el monto",IF($F13="","Falta la categoría",IF(AND($E13="Fijo",COUNTIF(Fijos_Concepto,$G13)=0),"El concepto no existe en la hoja Fijos",IF($J13="Pendiente","Movimiento pendiente de pago","OK")))))))
A14: =IF($B14="","",COUNT($B$7:$B14)) | C14: =IF($B14="","",IFERROR(MATCH($B14,Quincenas!$E$7:$E$30,1),"")) | D14: =IF($B14="","",MONTH($B14)) | L14: =IF($B14="","",IF($C14="","La fecha está fuera del año configurado",IF($E14="","Falta indicar el tipo",IF($H14="","Falta el monto",IF($F14="","Falta la categoría",IF(AND($E14="Fijo",COUNTIF(Fijos_Concepto,$G14)=0),"El concepto no existe en la hoja Fijos",IF($J14="Pendiente","Movimiento pendiente de pago","OK")))))))
A15: =IF($B15="","",COUNT($B$7:$B15)) | C15: =IF($B15="","",IFERROR(MATCH($B15,Quincenas!$E$7:$E$30,1),"")) | D15: =IF($B15="","",MONTH($B15)) | L15: =IF($B15="","",IF($C15="","La fecha está fuera del año configurado",IF($E15="","Falta indicar el tipo",IF($H15="","Falta el monto",IF($F15="","Falta la categoría",IF(AND($E15="Fijo",COUNTIF(Fijos_Concepto,$G15)=0),"El concepto no existe en la hoja Fijos",IF($J15="Pendiente","Movimiento pendiente de pago","OK")))))))
A16: =IF($B16="","",COUNT($B$7:$B16)) | C16: =IF($B16="","",IFERROR(MATCH($B16,Quincenas!$E$7:$E$30,1),"")) | D16: =IF($B16="","",MONTH($B16)) | L16: =IF($B16="","",IF($C16="","La fecha está fuera del año configurado",IF($E16="","Falta indicar el tipo",IF($H16="","Falta el monto",IF($F16="","Falta la categoría",IF(AND($E16="Fijo",COUNTIF(Fijos_Concepto,$G16)=0),"El concepto no existe en la hoja Fijos",IF($J16="Pendiente","Movimiento pendiente de pago","OK")))))))
A17: =IF($B17="","",COUNT($B$7:$B17)) | C17: =IF($B17="","",IFERROR(MATCH($B17,Quincenas!$E$7:$E$30,1),"")) | D17: =IF($B17="","",MONTH($B17)) | L17: =IF($B17="","",IF($C17="","La fecha está fuera del año configurado",IF($E17="","Falta indicar el tipo",IF($H17="","Falta el monto",IF($F17="","Falta la categoría",IF(AND($E17="Fijo",COUNTIF(Fijos_Concepto,$G17)=0),"El concepto no existe en la hoja Fijos",IF($J17="Pendiente","Movimiento pendiente de pago","OK")))))))
A18: =IF($B18="","",COUNT($B$7:$B18)) | C18: =IF($B18="","",IFERROR(MATCH($B18,Quincenas!$E$7:$E$30,1),"")) | D18: =IF($B18="","",MONTH($B18)) | L18: =IF($B18="","",IF($C18="","La fecha está fuera del año configurado",IF($E18="","Falta indicar el tipo",IF($H18="","Falta el monto",IF($F18="","Falta la categoría",IF(AND($E18="Fijo",COUNTIF(Fijos_Concepto,$G18)=0),"El concepto no existe en la hoja Fijos",IF($J18="Pendiente","Movimiento pendiente de pago","OK")))))))
A19: =IF($B19="","",COUNT($B$7:$B19)) | C19: =IF($B19="","",IFERROR(MATCH($B19,Quincenas!$E$7:$E$30,1),"")) | D19: =IF($B19="","",MONTH($B19)) | L19: =IF($B19="","",IF($C19="","La fecha está fuera del año configurado",IF($E19="","Falta indicar el tipo",IF($H19="","Falta el monto",IF($F19="","Falta la categoría",IF(AND($E19="Fijo",COUNTIF(Fijos_Concepto,$G19)=0),"El concepto no existe en la hoja Fijos",IF($J19="Pendiente","Movimiento pendiente de pago","OK")))))))
... A402: =IF($B402="","",COUNT($B$7:$B402)) | C402: =IF($B402="","",IFERROR(MATCH($B402,Quincenas!$E$7:$E$30,1),"")) | D402: =IF($B402="","",MONTH($B402)) | L402: =IF($B402="","",IF($C402="","La fecha está fuera del año configurado",IF($E402="","Falta indicar el tipo",IF($H402="","Falta el monto",IF($F402="","Falta la categoría",IF(AND($E402="Fijo",COUNTIF(Fijos_Concepto,$G402)=0),"El concepto no existe en la hoja Fijos",IF($J402="Pendiente","Movimiento pendiente de pago","OK")))))))

Sheet Control
A1: CONTROL DE PAGOS FIJOS · qué toca pagar, qué ya pagaste, qué se te pasó
B3: Quincena analizada: | C3: =Q_Activa -> 16 | E3: Para revisar otra quincena, cambia el número en Config (celda C8). Con 0 usa siempre la quincena de hoy.
B4: Periodo: | C4: =INDEX(Quincenas!$B$7:$B$30,Q_Activa)&" · "&INDEX(Quincenas!$D$7:$D$30,Q_Activa) -> Agosto · Q2
B5: Fechas: | C5: =TEXT(INDEX(Quincenas!$E$7:$E$30,Q_Activa),"DD/MM/YYYY")&" al "&TEXT(INDEX(Quincenas!$F$7:$F$30,Q_Activa),"DD/MM/YYYY") -> 16/08/2026 al 31/08/2026
A7: ID | B7: Categoría | C7: Concepto | D7: Presupuestado | E7: Se paga el | F7: Registrado | G7: Fecha en que lo pagaste | H7: Diferencia | I7: Estado | J7: Días restantes
A8: =IF(Fijos!$C7="","",Fijos!$A7) -> F01 | B8: =IF(Fijos!$C7="","",Fijos!$B7) -> Vivienda | C8: =IF(Fijos!$C7="","",Fijos!$C7) -> Apoyo Casa | D8: =IF($C8="","",IF(Fijos!$I7="No",0,IF(OR(Fijos!$G7="Ambas",Fijos!$G7=INDEX(Quincenas!$D$7:$D$30,Q_Activa)),Fijos!$D7,0))) -> 2500 | E8: =IF($C8="","",IF($D8=0,"",IF(Fijos!$F7="Quincenal",INDEX(Quincenas!$F$7:$F$30,Q_Activa),DATE(Anio,INDEX(Quincenas!$C$7:$C$30,Q_Activa),MIN(Fijos!$E7,DAY(INDEX(Quincenas!$F$7:$F$30,Q_Activa))))))) -> 46265 | F8: =IF($C8="","",SUMIFS(Reg_Monto,Reg_Concepto,$C8,Reg_Quincena,Q_Activa,Reg_Tipo,"Fijo")) -> 0 | G8: =IF($C8="","",IF($F8=0,"",SUMPRODUCT(MAX((Reg_Concepto=$C8)*(Reg_Quincena=Q_Activa)*(Reg_Tipo="Fijo")*Reg_Fecha)))) | H8: =IF($C8="","",$F8-$D8) -> -2500 | I8: =IF($C8="","",IF($D8=0,"No aplica",IF($F8>0,IF(ABS($H8)<1,"Pagado","Pagado (monto distinto)"),IF($E8<TODAY(),"VENCIDO sin registrar",IF($E8-TODAY()<=Dias_Aviso,"Por vencer","Pendiente"))))) -> Por vencer | J8: =IF(OR($C8="",$D8=0,$F8>0),"",$E8-TODAY()) -> 0
A9: =IF(Fijos!$C8="","",Fijos!$A8) -> F02 | B9: =IF(Fijos!$C8="","",Fijos!$B8) -> Transporte | C9: =IF(Fijos!$C8="","",Fijos!$C8) -> Pasajes y transporte | D9: =IF($C9="","",IF(Fijos!$I8="No",0,IF(OR(Fijos!$G8="Ambas",Fijos!$G8=INDEX(Quincenas!$D$7:$D$30,Q_Activa)),Fijos!$D8,0))) -> 2400 | E9: =IF($C9="","",IF($D9=0,"",IF(Fijos!$F8="Quincenal",INDEX(Quincenas!$F$7:$F$30,Q_Activa),DATE(Anio,INDEX(Quincenas!$C$7:$C$30,Q_Activa),MIN(Fijos!$E8,DAY(INDEX(Quincenas!$F$7:$F$30,Q_Activa))))))) -> 46265 | F9: =IF($C9="","",SUMIFS(Reg_Monto,Reg_Concepto,$C9,Reg_Quincena,Q_Activa,Reg_Tipo,"Fijo")) -> 0 | G9: =IF($C9="","",IF($F9=0,"",SUMPRODUCT(MAX((Reg_Concepto=$C9)*(Reg_Quincena=Q_Activa)*(Reg_Tipo="Fijo")*Reg_Fecha)))) | H9: =IF($C9="","",$F9-$D9) -> -2400 | I9: =IF($C9="","",IF($D9=0,"No aplica",IF($F9>0,IF(ABS($H9)<1,"Pagado","Pagado (monto distinto)"),IF($E9<TODAY(),"VENCIDO sin registrar",IF($E9-TODAY()<=Dias_Aviso,"Por vencer","Pendiente"))))) -> Por vencer | J9: =IF(OR($C9="",$D9=0,$F9>0),"",$E9-TODAY()) -> 0
A10: =IF(Fijos!$C9="","",Fijos!$A9) -> F03 | B10: =IF(Fijos!$C9="","",Fijos!$B9) -> Deudas y tarjetas | C10: =IF(Fijos!$C9="","",Fijos!$C9) -> Pago Perfume | D10: =IF($C10="","",IF(Fijos!$I9="No",0,IF(OR(Fijos!$G9="Ambas",Fijos!$G9=INDEX(Quincenas!$D$7:$D$30,Q_Activa)),Fijos!$D9,0))) -> 400 | E10: =IF($C10="","",IF($D10=0,"",IF(Fijos!$F9="Quincenal",INDEX(Quincenas!$F$7:$F$30,Q_Activa),DATE(Anio,INDEX(Quincenas!$C$7:$C$30,Q_Activa),MIN(Fijos!$E9,DAY(INDEX(Quincenas!$F$7:$F$30,Q_Activa))))))) -> 46265 | F10: =IF($C10="","",SUMIFS(Reg_Monto,Reg_Concepto,$C10,Reg_Quincena,Q_Activa,Reg_Tipo,"Fijo")) -> 0 | G10: =IF($C10="","",IF($F10=0,"",SUMPRODUCT(MAX((Reg_Concepto=$C10)*(Reg_Quincena=Q_Activa)*(Reg_Tipo="Fijo")*Reg_Fecha)))) | H10: =IF($C10="","",$F10-$D10) -> -400 | I10: =IF($C10="","",IF($D10=0,"No aplica",IF($F10>0,IF(ABS($H10)<1,"Pagado","Pagado (monto distinto)"),IF($E10<TODAY(),"VENCIDO sin registrar",IF($E10-TODAY()<=Dias_Aviso,"Por vencer","Pendiente"))))) -> Por vencer | J10: =IF(OR($C10="",$D10=0,$F10>0),"",$E10-TODAY()) -> 0
A11: =IF(Fijos!$C10="","",Fijos!$A10) -> F04 | B11: =IF(Fijos!$C10="","",Fijos!$B10) -> Suscripciones | C11: =IF(Fijos!$C10="","",Fijos!$C10) -> Streaming | D11: =IF($C11="","",IF(Fijos!$I10="No",0,IF(OR(Fijos!$G10="Ambas",Fijos!$G10=INDEX(Quincenas!$D$7:$D$30,Q_Activa)),Fijos!$D10,0))) -> 400 | E11: =IF($C11="","",IF($D11=0,"",IF(Fijos!$F10="Quincenal",INDEX(Quincenas!$F$7:$F$30,Q_Activa),DATE(Anio,INDEX(Quincenas!$C$7:$C$30,Q_Activa),MIN(Fijos!$E10,DAY(INDEX(Quincenas!$F$7:$F$30,Q_Activa))))))) -> 46265 | F11: =IF($C11="","",SUMIFS(Reg_Monto,Reg_Concepto,$C11,Reg_Quincena,Q_Activa,Reg_Tipo,"Fijo")) -> 0 | G11: =IF($C11="","",IF($F11=0,"",SUMPRODUCT(MAX((Reg_Concepto=$C11)*(Reg_Quincena=Q_Activa)*(Reg_Tipo="Fijo")*Reg_Fecha)))) | H11: =IF($C11="","",$F11-$D11) -> -400 | I11: =IF($C11="","",IF($D11=0,"No aplica",IF($F11>0,IF(ABS($H11)<1,"Pagado","Pagado (monto distinto)"),IF($E11<TODAY(),"VENCIDO sin registrar",IF($E11-TODAY()<=Dias_Aviso,"Por vencer","Pendiente"))))) -> Por vencer | J11: =IF(OR($C11="",$D11=0,$F11>0),"",$E11-TODAY()) -> 0
A12: =IF(Fijos!$C11="","",Fijos!$A11) -> F05 | B12: =IF(Fijos!$C11="","",Fijos!$B11) -> Internet y teléfono | C12: =IF(Fijos!$C11="","",Fijos!$C11) -> Telefono | D12: =IF($C12="","",IF(Fijos!$I11="No",0,IF(OR(Fijos!$G11="Ambas",Fijos!$G11=INDEX(Quincenas!$D$7:$D$30,Q_Activa)),Fijos!$D11,0))) -> 700 | E12: =IF($C12="","",IF($D12=0,"",IF(Fijos!$F11="Quincenal",INDEX(Quincenas!$F$7:$F$30,Q_Activa),DATE(Anio,INDEX(Quincenas!$C$7:$C$30,Q_Activa),MIN(Fijos!$E11,DAY(INDEX(Quincenas!$F$7:$F$30,Q_Activa))))))) -> 46262 | F12: =IF($C12="","",SUMIFS(Reg_Monto,Reg_Concepto,$C12,Reg_Quincena,Q_Activa,Reg_Tipo,"Fijo")) -> 0 | G12: =IF($C12="","",IF($F12=0,"",SUMPRODUCT(MAX((Reg_Concepto=$C12)*(Reg_Quincena=Q_Activa)*(Reg_Tipo="Fijo")*Reg_Fecha)))) | H12: =IF($C12="","",$F12-$D12) -> -700 | I12: =IF($C12="","",IF($D12=0,"No aplica",IF($F12>0,IF(ABS($H12)<1,"Pagado","Pagado (monto distinto)"),IF($E12<TODAY(),"VENCIDO sin registrar",IF($E12-TODAY()<=Dias_Aviso,"Por vencer","Pendiente"))))) -> VENCIDO sin registrar | J12: =IF(OR($C12="",$D12=0,$F12>0),"",$E12-TODAY()) -> -3
A13: =IF(Fijos!$C12="","",Fijos!$A12) | B13: =IF(Fijos!$C12="","",Fijos!$B12) | C13: =IF(Fijos!$C12="","",Fijos!$C12) | D13: =IF($C13="","",IF(Fijos!$I12="No",0,IF(OR(Fijos!$G12="Ambas",Fijos!$G12=INDEX(Quincenas!$D$7:$D$30,Q_Activa)),Fijos!$D12,0))) | E13: =IF($C13="","",IF($D13=0,"",IF(Fijos!$F12="Quincenal",INDEX(Quincenas!$F$7:$F$30,Q_Activa),DATE(Anio,INDEX(Quincenas!$C$7:$C$30,Q_Activa),MIN(Fijos!$E12,DAY(INDEX(Quincenas!$F$7:$F$30,Q_Activa))))))) | F13: =IF($C13="","",SUMIFS(Reg_Monto,Reg_Concepto,$C13,Reg_Quincena,Q_Activa,Reg_Tipo,"Fijo")) | G13: =IF($C13="","",IF($F13=0,"",SUMPRODUCT(MAX((Reg_Concepto=$C13)*(Reg_Quincena=Q_Activa)*(Reg_Tipo="Fijo")*Reg_Fecha)))) | H13: =IF($C13="","",$F13-$D13) | I13: =IF($C13="","",IF($D13=0,"No aplica",IF($F13>0,IF(ABS($H13)<1,"Pagado","Pagado (monto distinto)"),IF($E13<TODAY(),"VENCIDO sin registrar",IF($E13-TODAY()<=Dias_Aviso,"Por vencer","Pendiente"))))) | J13: =IF(OR($C13="",$D13=0,$F13>0),"",$E13-TODAY())
A14: =IF(Fijos!$C13="","",Fijos!$A13) | B14: =IF(Fijos!$C13="","",Fijos!$B13) | C14: =IF(Fijos!$C13="","",Fijos!$C13) | D14: =IF($C14="","",IF(Fijos!$I13="No",0,IF(OR(Fijos!$G13="Ambas",Fijos!$G13=INDEX(Quincenas!$D$7:$D$30,Q_Activa)),Fijos!$D13,0))) | E14: =IF($C14="","",IF($D14=0,"",IF(Fijos!$F13="Quincenal",INDEX(Quincenas!$F$7:$F$30,Q_Activa),DATE(Anio,INDEX(Quincenas!$C$7:$C$30,Q_Activa),MIN(Fijos!$E13,DAY(INDEX(Quincenas!$F$7:$F$30,Q_Activa))))))) | F14: =IF($C14="","",SUMIFS(Reg_Monto,Reg_Concepto,$C14,Reg_Quincena,Q_Activa,Reg_Tipo,"Fijo")) | G14: =IF($C14="","",IF($F14=0,"",SUMPRODUCT(MAX((Reg_Concepto=$C14)*(Reg_Quincena=Q_Activa)*(Reg_Tipo="Fijo")*Reg_Fecha)))) | H14: =IF($C14="","",$F14-$D14) | I14: =IF($C14="","",IF($D14=0,"No aplica",IF($F14>0,IF(ABS($H14)<1,"Pagado","Pagado (monto distinto)"),IF($E14<TODAY(),"VENCIDO sin registrar",IF($E14-TODAY()<=Dias_Aviso,"Por vencer","Pendiente"))))) | J14: =IF(OR($C14="",$D14=0,$F14>0),"",$E14-TODAY())
A15: =IF(Fijos!$C14="","",Fijos!$A14) | B15: =IF(Fijos!$C14="","",Fijos!$B14) | C15: =IF(Fijos!$C14="","",Fijos!$C14) | D15: =IF($C15="","",IF(Fijos!$I14="No",0,IF(OR(Fijos!$G14="Ambas",Fijos!$G14=INDEX(Quincenas!$D$7:$D$30,Q_Activa)),Fijos!$D14,0))) | E15: =IF($C15="","",IF($D15=0,"",IF(Fijos!$F14="Quincenal",INDEX(Quincenas!$F$7:$F$30,Q_Activa),DATE(Anio,INDEX(Quincenas!$C$7:$C$30,Q_Activa),MIN(Fijos!$E14,DAY(INDEX(Quincenas!$F$7:$F$30,Q_Activa))))))) | F15: =IF($C15="","",SUMIFS(Reg_Monto,Reg_Concepto,$C15,Reg_Quincena,Q_Activa,Reg_Tipo,"Fijo")) | G15: =IF($C15="","",IF($F15=0,"",SUMPRODUCT(MAX((Reg_Concepto=$C15)*(Reg_Quincena=Q_Activa)*(Reg_Tipo="Fijo")*Reg_Fecha)))) | H15: =IF($C15="","",$F15-$D15) | I15: =IF($C15="","",IF($D15=0,"No aplica",IF($F15>0,IF(ABS($H15)<1,"Pagado","Pagado (monto distinto)"),IF($E15<TODAY(),"VENCIDO sin registrar",IF($E15-TODAY()<=Dias_Aviso,"Por vencer","Pendiente"))))) | J15: =IF(OR($C15="",$D15=0,$F15>0),"",$E15-TODAY())
A16: =IF(Fijos!$C15="","",Fijos!$A15) | B16: =IF(Fijos!$C15="","",Fijos!$B15) | C16: =IF(Fijos!$C15="","",Fijos!$C15) | D16: =IF($C16="","",IF(Fijos!$I15="No",0,IF(OR(Fijos!$G15="Ambas",Fijos!$G15=INDEX(Quincenas!$D$7:$D$30,Q_Activa)),Fijos!$D15,0))) | E16: =IF($C16="","",IF($D16=0,"",IF(Fijos!$F15="Quincenal",INDEX(Quincenas!$F$7:$F$30,Q_Activa),DATE(Anio,INDEX(Quincenas!$C$7:$C$30,Q_Activa),MIN(Fijos!$E15,DAY(INDEX(Quincenas!$F$7:$F$30,Q_Activa))))))) | F16: =IF($C16="","",SUMIFS(Reg_Monto,Reg_Concepto,$C16,Reg_Quincena,Q_Activa,Reg_Tipo,"Fijo")) | G16: =IF($C16="","",IF($F16=0,"",SUMPRODUCT(MAX((Reg_Concepto=$C16)*(Reg_Quincena=Q_Activa)*(Reg_Tipo="Fijo")*Reg_Fecha)))) | H16: =IF($C16="","",$F16-$D16) | I16: =IF($C16="","",IF($D16=0,"No aplica",IF($F16>0,IF(ABS($H16)<1,"Pagado","Pagado (monto distinto)"),IF($E16<TODAY(),"VENCIDO sin registrar",IF($E16-TODAY()<=Dias_Aviso,"Por vencer","Pendiente"))))) | J16: =IF(OR($C16="",$D16=0,$F16>0),"",$E16-TODAY())
A17: =IF(Fijos!$C16="","",Fijos!$A16) | B17: =IF(Fijos!$C16="","",Fijos!$B16) | C17: =IF(Fijos!$C16="","",Fijos!$C16) | D17: =IF($C17="","",IF(Fijos!$I16="No",0,IF(OR(Fijos!$G16="Ambas",Fijos!$G16=INDEX(Quincenas!$D$7:$D$30,Q_Activa)),Fijos!$D16,0))) | E17: =IF($C17="","",IF($D17=0,"",IF(Fijos!$F16="Quincenal",INDEX(Quincenas!$F$7:$F$30,Q_Activa),DATE(Anio,INDEX(Quincenas!$C$7:$C$30,Q_Activa),MIN(Fijos!$E16,DAY(INDEX(Quincenas!$F$7:$F$30,Q_Activa))))))) | F17: =IF($C17="","",SUMIFS(Reg_Monto,Reg_Concepto,$C17,Reg_Quincena,Q_Activa,Reg_Tipo,"Fijo")) | G17: =IF($C17="","",IF($F17=0,"",SUMPRODUCT(MAX((Reg_Concepto=$C17)*(Reg_Quincena=Q_Activa)*(Reg_Tipo="Fijo")*Reg_Fecha)))) | H17: =IF($C17="","",$F17-$D17) | I17: =IF($C17="","",IF($D17=0,"No aplica",IF($F17>0,IF(ABS($H17)<1,"Pagado","Pagado (monto distinto)"),IF($E17<TODAY(),"VENCIDO sin registrar",IF($E17-TODAY()<=Dias_Aviso,"Por vencer","Pendiente"))))) | J17: =IF(OR($C17="",$D17=0,$F17>0),"",$E17-TODAY())
A18: =IF(Fijos!$C17="","",Fijos!$A17) | B18: =IF(Fijos!$C17="","",Fijos!$B17) | C18: =IF(Fijos!$C17="","",Fijos!$C17) | D18: =IF($C18="","",IF(Fijos!$I17="No",0,IF(OR(Fijos!$G17="Ambas",Fijos!$G17=INDEX(Quincenas!$D$7:$D$30,Q_Activa)),Fijos!$D17,0))) | E18: =IF($C18="","",IF($D18=0,"",IF(Fijos!$F17="Quincenal",INDEX(Quincenas!$F$7:$F$30,Q_Activa),DATE(Anio,INDEX(Quincenas!$C$7:$C$30,Q_Activa),MIN(Fijos!$E17,DAY(INDEX(Quincenas!$F$7:$F$30,Q_Activa))))))) | F18: =IF($C18="","",SUMIFS(Reg_Monto,Reg_Concepto,$C18,Reg_Quincena,Q_Activa,Reg_Tipo,"Fijo")) | G18: =IF($C18="","",IF($F18=0,"",SUMPRODUCT(MAX((Reg_Concepto=$C18)*(Reg_Quincena=Q_Activa)*(Reg_Tipo="Fijo")*Reg_Fecha)))) | H18: =IF($C18="","",$F18-$D18) | I18: =IF($C18="","",IF($D18=0,"No aplica",IF($F18>0,IF(ABS($H18)<1,"Pagado","Pagado (monto distinto)"),IF($E18<TODAY(),"VENCIDO sin registrar",IF($E18-TODAY()<=Dias_Aviso,"Por vencer","Pendiente"))))) | J18: =IF(OR($C18="",$D18=0,$F18>0),"",$E18-TODAY())
A19: =IF(Fijos!$C18="","",Fijos!$A18) | B19: =IF(Fijos!$C18="","",Fijos!$B18) | C19: =IF(Fijos!$C18="","",Fijos!$C18) | D19: =IF($C19="","",IF(Fijos!$I18="No",0,IF(OR(Fijos!$G18="Ambas",Fijos!$G18=INDEX(Quincenas!$D$7:$D$30,Q_Activa)),Fijos!$D18,0))) | E19: =IF($C19="","",IF($D19=0,"",IF(Fijos!$F18="Quincenal",INDEX(Quincenas!$F$7:$F$30,Q_Activa),DATE(Anio,INDEX(Quincenas!$C$7:$C$30,Q_Activa),MIN(Fijos!$E18,DAY(INDEX(Quincenas!$F$7:$F$30,Q_Activa))))))) | F19: =IF($C19="","",SUMIFS(Reg_Monto,Reg_Concepto,$C19,Reg_Quincena,Q_Activa,Reg_Tipo,"Fijo")) | G19: =IF($C19="","",IF($F19=0,"",SUMPRODUCT(MAX((Reg_Concepto=$C19)*(Reg_Quincena=Q_Activa)*(Reg_Tipo="Fijo")*Reg_Fecha)))) | H19: =IF($C19="","",$F19-$D19) | I19: =IF($C19="","",IF($D19=0,"No aplica",IF($F19>0,IF(ABS($H19)<1,"Pagado","Pagado (monto distinto)"),IF($E19<TODAY(),"VENCIDO sin registrar",IF($E19-TODAY()<=Dias_Aviso,"Por vencer","Pendiente"))))) | J19: =IF(OR($C19="",$D19=0,$F19>0),"",$E19-TODAY())
... A29: =IF(Fijos!$C28="","",Fijos!$A28) | B29: =IF(Fijos!$C28="","",Fijos!$B28) | C29: =IF(Fijos!$C28="","",Fijos!$C28) | D29: =IF($C29="","",IF(Fijos!$I28="No",0,IF(OR(Fijos!$G28="Ambas",Fijos!$G28=INDEX(Quincenas!$D$7:$D$30,Q_Activa)),Fijos!$D28,0))) | E29: =IF($C29="","",IF($D29=0,"",IF(Fijos!$F28="Quincenal",INDEX(Quincenas!$F$7:$F$30,Q_Activa),DATE(Anio,INDEX(Quincenas!$C$7:$C$30,Q_Activa),MIN(Fijos!$E28,DAY(INDEX(Quincenas!$F$7:$F$30,Q_Activa))))))) | F29: =IF($C29="","",SUMIFS(Reg_Monto,Reg_Concepto,$C29,Reg_Quincena,Q_Activa,Reg_Tipo,"Fijo")) | G29: =IF($C29="","",IF($F29=0,"",SUMPRODUCT(MAX((Reg_Concepto=$C29)*(Reg_Quincena=Q_Activa)*(Reg_Tipo="Fijo")*Reg_Fecha)))) | H29: =IF($C29="","",$F29-$D29) | I29: =IF($C29="","",IF($D29=0,"No aplica",IF($F29>0,IF(ABS($H29)<1,"Pagado","Pagado (monto distinto)"),IF($E29<TODAY(),"VENCIDO sin registrar",IF($E29-TODAY()<=Dias_Aviso,"Por vencer","Pendiente"))))) | J29: =IF(OR($C29="",$D29=0,$F29>0),"",$E29-TODAY())
A30: TOTALES DE LA QUINCENA | D30: =SUM(D8:D29) -> 6400 | F30: =SUM(F8:F29) -> 0 | H30: =SUM(H8:H29) -> -6400
B32: RESUMEN DE PAGOS FIJOS DE ESTA QUINCENA
B33: Total presupuestado en fijos | D33: =SUM($D$8:$D$29) -> 6400
B34: Total ya pagado y registrado | D34: =SUM($F$8:$F$29) -> 0
B35: Pendiente por pagar | D35: =$D$33-$D$34 -> 6400
B36: Pagos vencidos sin registrar | D36: =COUNTIF($I$8:$I$29,"VENCIDO sin registrar") -> 1
B37: Pagos por vencer pronto | D37: =COUNTIF($I$8:$I$29,"Por vencer") -> 4
B38: Pagos ya registrados | D38: =COUNTIF($I$8:$I$29,"Pagado*") -> 0
B39: Pagos pendientes todavía sin vencer | D39: =COUNTIF($I$8:$I$29,"Pendiente") -> 0

Sheet Historial
A1: HISTORIAL ANUAL DE PAGOS FIJOS · monto registrado en cada quincena (C$)
A2: Rojo = esa quincena ya cerró y el fijo no aparece registrado: lo más probable es que se te olvidara anotarlo. Verde = registrado.
A3: Solo se revisan las quincenas posteriores a la fecha 'Llevo el control desde' de la hoja Config, para no reclamarte meses que nunca usaste.
A6: ID | B6: Concepto | C6: Frecuencia | D6: Aplica | E6: Activo | F6: 1 | G6: 2 | H6: 3 | I6: 4 | J6: 5 | K6: 6 | L6: 7 | M6: 8 | N6: 9 | O6: 10 | P6: 11 | Q6: 12 | R6: 13 | S6: 14 | T6: 15 | U6: 16 | V6: 17 | W6: 18 | X6: 19 | Y6: 20 | Z6: 21 | AA6: 22 | AB6: 23 | AC6: 24
A7: Periodo del mes | F7: =INDEX(Quincenas!$D$7:$D$30,F$6) -> Q1 | G7: =INDEX(Quincenas!$D$7:$D$30,G$6) -> Q2 | H7: =INDEX(Quincenas!$D$7:$D$30,H$6) -> Q1 | I7: =INDEX(Quincenas!$D$7:$D$30,I$6) -> Q2 | J7: =INDEX(Quincenas!$D$7:$D$30,J$6) -> Q1 | K7: =INDEX(Quincenas!$D$7:$D$30,K$6) -> Q2 | L7: =INDEX(Quincenas!$D$7:$D$30,L$6) -> Q1 | M7: =INDEX(Quincenas!$D$7:$D$30,M$6) -> Q2 | ... AC7: =INDEX(Quincenas!$D$7:$D$30,AC$6) -> Q2
A8: La quincena cierra el | F8: =INDEX(Quincenas!$F$7:$F$30,F$6) -> 46037 | G8: =INDEX(Quincenas!$F$7:$F$30,G$6) -> 46053 | H8: =INDEX(Quincenas!$F$7:$F$30,H$6) -> 46068 | I8: =INDEX(Quincenas!$F$7:$F$30,I$6) -> 46081 | J8: =INDEX(Quincenas!$F$7:$F$30,J$6) -> 46096 | K8: =INDEX(Quincenas!$F$7:$F$30,K$6) -> 46112 | L8: =INDEX(Quincenas!$F$7:$F$30,L$6) -> 46127 | M8: =INDEX(Quincenas!$F$7:$F$30,M$6) -> 46142 | ... AC8: =INDEX(Quincenas!$F$7:$F$30,AC$6) -> 46387
A9: =IF(Fijos!$C7="","",Fijos!$A7) -> F01 | B9: =IF(Fijos!$C7="","",Fijos!$C7) -> Apoyo Casa | C9: =IF(Fijos!$C7="","",Fijos!$F7) -> Quincenal | D9: =IF(Fijos!$C7="","",Fijos!$G7) -> Ambas | E9: =IF(Fijos!$C7="","",Fijos!$I7) -> Sí | F9: =IF($B9="","",SUMIFS(Reg_Monto,Reg_Concepto,$B9,Reg_Quincena,F$6,Reg_Tipo,"Fijo")) -> 0 | G9: =IF($B9="","",SUMIFS(Reg_Monto,Reg_Concepto,$B9,Reg_Quincena,G$6,Reg_Tipo,"Fijo")) -> 0 | H9: =IF($B9="","",SUMIFS(Reg_Monto,Reg_Concepto,$B9,Reg_Quincena,H$6,Reg_Tipo,"Fijo")) -> 0 | I9: =IF($B9="","",SUMIFS(Reg_Monto,Reg_Concepto,$B9,Reg_Quincena,I$6,Reg_Tipo,"Fijo")) -> 0 | J9: =IF($B9="","",SUMIFS(Reg_Monto,Reg_Concepto,$B9,Reg_Quincena,J$6,Reg_Tipo,"Fijo")) -> 0 | K9: =IF($B9="","",SUMIFS(Reg_Monto,Reg_Concepto,$B9,Reg_Quincena,K$6,Reg_Tipo,"Fijo")) -> 0 | L9: =IF($B9="","",SUMIFS(Reg_Monto,Reg_Concepto,$B9,Reg_Quincena,L$6,Reg_Tipo,"Fijo")) -> 0 | M9: =IF($B9="","",SUMIFS(Reg_Monto,Reg_Concepto,$B9,Reg_Quincena,M$6,Reg_Tipo,"Fijo")) -> 0 | ... AC9: =IF($B9="","",SUMIFS(Reg_Monto,Reg_Concepto,$B9,Reg_Quincena,AC$6,Reg_Tipo,"Fijo")) -> 0
A10: =IF(Fijos!$C8="","",Fijos!$A8) -> F02 | B10: =IF(Fijos!$C8="","",Fijos!$C8) -> Pasajes y transporte | C10: =IF(Fijos!$C8="","",Fijos!$F8) -> Quincenal | D10: =IF(Fijos!$C8="","",Fijos!$G8) -> Ambas | E10: =IF(Fijos!$C8="","",Fijos!$I8) -> Sí | F10: =IF($B10="","",SUMIFS(Reg_Monto,Reg_Concepto,$B10,Reg_Quincena,F$6,Reg_Tipo,"Fijo")) -> 0 | G10: =IF($B10="","",SUMIFS(Reg_Monto,Reg_Concepto,$B10,Reg_Quincena,G$6,Reg_Tipo,"Fijo")) -> 0 | H10: =IF($B10="","",SUMIFS(Reg_Monto,Reg_Concepto,$B10,Reg_Quincena,H$6,Reg_Tipo,"Fijo")) -> 0 | I10: =IF($B10="","",SUMIFS(Reg_Monto,Reg_Concepto,$B10,Reg_Quincena,I$6,Reg_Tipo,"Fijo")) -> 0 | J10: =IF($B10="","",SUMIFS(Reg_Monto,Reg_Concepto,$B10,Reg_Quincena,J$6,Reg_Tipo,"Fijo")) -> 0 | K10: =IF($B10="","",SUMIFS(Reg_Monto,Reg_Concepto,$B10,Reg_Quincena,K$6,Reg_Tipo,"Fijo")) -> 0 | L10: =IF($B10="","",SUMIFS(Reg_Monto,Reg_Concepto,$B10,Reg_Quincena,L$6,Reg_Tipo,"Fijo")) -> 0 | M10: =IF($B10="","",SUMIFS(Reg_Monto,Reg_Concepto,$B10,Reg_Quincena,M$6,Reg_Tipo,"Fijo")) -> 0 | ... AC10: =IF($B10="","",SUMIFS(Reg_Monto,Reg_Concepto,$B10,Reg_Quincena,AC$6,Reg_Tipo,"Fijo")) -> 0
A11: =IF(Fijos!$C9="","",Fijos!$A9) -> F03 | B11: =IF(Fijos!$C9="","",Fijos!$C9) -> Pago Perfume | C11: =IF(Fijos!$C9="","",Fijos!$F9) -> Quincenal | D11: =IF(Fijos!$C9="","",Fijos!$G9) -> Ambas | E11: =IF(Fijos!$C9="","",Fijos!$I9) -> Sí | F11: =IF($B11="","",SUMIFS(Reg_Monto,Reg_Concepto,$B11,Reg_Quincena,F$6,Reg_Tipo,"Fijo")) -> 0 | G11: =IF($B11="","",SUMIFS(Reg_Monto,Reg_Concepto,$B11,Reg_Quincena,G$6,Reg_Tipo,"Fijo")) -> 0 | H11: =IF($B11="","",SUMIFS(Reg_Monto,Reg_Concepto,$B11,Reg_Quincena,H$6,Reg_Tipo,"Fijo")) -> 0 | I11: =IF($B11="","",SUMIFS(Reg_Monto,Reg_Concepto,$B11,Reg_Quincena,I$6,Reg_Tipo,"Fijo")) -> 0 | J11: =IF($B11="","",SUMIFS(Reg_Monto,Reg_Concepto,$B11,Reg_Quincena,J$6,Reg_Tipo,"Fijo")) -> 0 | K11: =IF($B11="","",SUMIFS(Reg_Monto,Reg_Concepto,$B11,Reg_Quincena,K$6,Reg_Tipo,"Fijo")) -> 0 | L11: =IF($B11="","",SUMIFS(Reg_Monto,Reg_Concepto,$B11,Reg_Quincena,L$6,Reg_Tipo,"Fijo")) -> 0 | M11: =IF($B11="","",SUMIFS(Reg_Monto,Reg_Concepto,$B11,Reg_Quincena,M$6,Reg_Tipo,"Fijo")) -> 0 | ... AC11: =IF($B11="","",SUMIFS(Reg_Monto,Reg_Concepto,$B11,Reg_Quincena,AC$6,Reg_Tipo,"Fijo")) -> 0
A12: =IF(Fijos!$C10="","",Fijos!$A10) -> F04 | B12: =IF(Fijos!$C10="","",Fijos!$C10) -> Streaming | C12: =IF(Fijos!$C10="","",Fijos!$F10) -> Quincenal | D12: =IF(Fijos!$C10="","",Fijos!$G10) -> Ambas | E12: =IF(Fijos!$C10="","",Fijos!$I10) -> Sí | F12: =IF($B12="","",SUMIFS(Reg_Monto,Reg_Concepto,$B12,Reg_Quincena,F$6,Reg_Tipo,"Fijo")) -> 0 | G12: =IF($B12="","",SUMIFS(Reg_Monto,Reg_Concepto,$B12,Reg_Quincena,G$6,Reg_Tipo,"Fijo")) -> 0 | H12: =IF($B12="","",SUMIFS(Reg_Monto,Reg_Concepto,$B12,Reg_Quincena,H$6,Reg_Tipo,"Fijo")) -> 0 | I12: =IF($B12="","",SUMIFS(Reg_Monto,Reg_Concepto,$B12,Reg_Quincena,I$6,Reg_Tipo,"Fijo")) -> 0 | J12: =IF($B12="","",SUMIFS(Reg_Monto,Reg_Concepto,$B12,Reg_Quincena,J$6,Reg_Tipo,"Fijo")) -> 0 | K12: =IF($B12="","",SUMIFS(Reg_Monto,Reg_Concepto,$B12,Reg_Quincena,K$6,Reg_Tipo,"Fijo")) -> 0 | L12: =IF($B12="","",SUMIFS(Reg_Monto,Reg_Concepto,$B12,Reg_Quincena,L$6,Reg_Tipo,"Fijo")) -> 0 | M12: =IF($B12="","",SUMIFS(Reg_Monto,Reg_Concepto,$B12,Reg_Quincena,M$6,Reg_Tipo,"Fijo")) -> 0 | ... AC12: =IF($B12="","",SUMIFS(Reg_Monto,Reg_Concepto,$B12,Reg_Quincena,AC$6,Reg_Tipo,"Fijo")) -> 0
A13: =IF(Fijos!$C11="","",Fijos!$A11) -> F05 | B13: =IF(Fijos!$C11="","",Fijos!$C11) -> Telefono | C13: =IF(Fijos!$C11="","",Fijos!$F11) -> Mensual | D13: =IF(Fijos!$C11="","",Fijos!$G11) -> Q2 | E13: =IF(Fijos!$C11="","",Fijos!$I11) -> Sí | F13: =IF($B13="","",SUMIFS(Reg_Monto,Reg_Concepto,$B13,Reg_Quincena,F$6,Reg_Tipo,"Fijo")) -> 0 | G13: =IF($B13="","",SUMIFS(Reg_Monto,Reg_Concepto,$B13,Reg_Quincena,G$6,Reg_Tipo,"Fijo")) -> 0 | H13: =IF($B13="","",SUMIFS(Reg_Monto,Reg_Concepto,$B13,Reg_Quincena,H$6,Reg_Tipo,"Fijo")) -> 0 | I13: =IF($B13="","",SUMIFS(Reg_Monto,Reg_Concepto,$B13,Reg_Quincena,I$6,Reg_Tipo,"Fijo")) -> 0 | J13: =IF($B13="","",SUMIFS(Reg_Monto,Reg_Concepto,$B13,Reg_Quincena,J$6,Reg_Tipo,"Fijo")) -> 0 | K13: =IF($B13="","",SUMIFS(Reg_Monto,Reg_Concepto,$B13,Reg_Quincena,K$6,Reg_Tipo,"Fijo")) -> 0 | L13: =IF($B13="","",SUMIFS(Reg_Monto,Reg_Concepto,$B13,Reg_Quincena,L$6,Reg_Tipo,"Fijo")) -> 0 | M13: =IF($B13="","",SUMIFS(Reg_Monto,Reg_Concepto,$B13,Reg_Quincena,M$6,Reg_Tipo,"Fijo")) -> 0 | ... AC13: =IF($B13="","",SUMIFS(Reg_Monto,Reg_Concepto,$B13,Reg_Quincena,AC$6,Reg_Tipo,"Fijo")) -> 0
A14: =IF(Fijos!$C12="","",Fijos!$A12) | B14: =IF(Fijos!$C12="","",Fijos!$C12) | C14: =IF(Fijos!$C12="","",Fijos!$F12) | D14: =IF(Fijos!$C12="","",Fijos!$G12) | E14: =IF(Fijos!$C12="","",Fijos!$I12) | F14: =IF($B14="","",SUMIFS(Reg_Monto,Reg_Concepto,$B14,Reg_Quincena,F$6,Reg_Tipo,"Fijo")) | G14: =IF($B14="","",SUMIFS(Reg_Monto,Reg_Concepto,$B14,Reg_Quincena,G$6,Reg_Tipo,"Fijo")) | H14: =IF($B14="","",SUMIFS(Reg_Monto,Reg_Concepto,$B14,Reg_Quincena,H$6,Reg_Tipo,"Fijo")) | I14: =IF($B14="","",SUMIFS(Reg_Monto,Reg_Concepto,$B14,Reg_Quincena,I$6,Reg_Tipo,"Fijo")) | J14: =IF($B14="","",SUMIFS(Reg_Monto,Reg_Concepto,$B14,Reg_Quincena,J$6,Reg_Tipo,"Fijo")) | K14: =IF($B14="","",SUMIFS(Reg_Monto,Reg_Concepto,$B14,Reg_Quincena,K$6,Reg_Tipo,"Fijo")) | L14: =IF($B14="","",SUMIFS(Reg_Monto,Reg_Concepto,$B14,Reg_Quincena,L$6,Reg_Tipo,"Fijo")) | M14: =IF($B14="","",SUMIFS(Reg_Monto,Reg_Concepto,$B14,Reg_Quincena,M$6,Reg_Tipo,"Fijo")) | ... AC14: =IF($B14="","",SUMIFS(Reg_Monto,Reg_Concepto,$B14,Reg_Quincena,AC$6,Reg_Tipo,"Fijo"))
